[2024-08-07T15:30:42.327+0000] {local_task_job_runner.py:120} INFO - ::group::Pre task execution logs
[2024-08-07T15:30:42.350+0000] {taskinstance.py:2076} INFO - Dependencies all met for dep_context=non-requeueable deps ti=<TaskInstance: dag_prueba_tecnica.limpieza scheduled__2024-07-28T00:00:00+00:00 [queued]>
[2024-08-07T15:30:42.356+0000] {taskinstance.py:2076} INFO - Dependencies all met for dep_context=requeueable deps ti=<TaskInstance: dag_prueba_tecnica.limpieza scheduled__2024-07-28T00:00:00+00:00 [queued]>
[2024-08-07T15:30:42.356+0000] {taskinstance.py:2306} INFO - Starting attempt 2 of 6
[2024-08-07T15:30:42.368+0000] {taskinstance.py:2330} INFO - Executing <Task(PythonOperator): limpieza> on 2024-07-28 00:00:00+00:00
[2024-08-07T15:30:42.376+0000] {warnings.py:112} WARNING - /home/***/.local/lib/python3.12/site-packages/***/task/task_runner/standard_task_runner.py:62: DeprecationWarning: This process (pid=242) is multi-threaded, use of fork() may lead to deadlocks in the child.
  pid = os.fork()

[2024-08-07T15:30:42.377+0000] {standard_task_runner.py:90} INFO - Running: ['***', 'tasks', 'run', 'dag_prueba_tecnica', 'limpieza', 'scheduled__2024-07-28T00:00:00+00:00', '--job-id', '98', '--raw', '--subdir', 'DAGS_FOLDER/dag_prueba_tecnica.py', '--cfg-path', '/tmp/tmpxccv2hoc']
[2024-08-07T15:30:42.378+0000] {standard_task_runner.py:64} INFO - Started process 255 to run task
[2024-08-07T15:30:42.378+0000] {standard_task_runner.py:91} INFO - Job 98: Subtask limpieza
[2024-08-07T15:30:42.416+0000] {task_command.py:426} INFO - Running <TaskInstance: dag_prueba_tecnica.limpieza scheduled__2024-07-28T00:00:00+00:00 [running]> on host 278ba5711b2c
[2024-08-07T15:30:42.478+0000] {taskinstance.py:2648} INFO - Exporting env vars: AIRFLOW_CTX_DAG_OWNER='miguel_guimarey' AIRFLOW_CTX_DAG_ID='dag_prueba_tecnica' AIRFLOW_CTX_TASK_ID='limpieza' AIRFLOW_CTX_EXECUTION_DATE='2024-07-28T00:00:00+00:00' AIRFLOW_CTX_TRY_NUMBER='2' AIRFLOW_CTX_DAG_RUN_ID='scheduled__2024-07-28T00:00:00+00:00'
[2024-08-07T15:30:42.479+0000] {taskinstance.py:430} INFO - ::endgroup::
[2024-08-07T15:30:45.312+0000] {warnings.py:112} WARNING - /opt/***/dags/dag_prueba_tecnica.py:37: FutureWarning: Passing literal json to 'read_json' is deprecated and will be removed in a future version. To read from a literal string, wrap it in a 'StringIO' object.
  df = pd.read_json(data, orient='records')

[2024-08-07T15:30:56.770+0000] {base.py:84} INFO - Using connection ID 'postgres_localhost' for task execution.
[2024-08-07T15:30:56.781+0000] {base.py:84} INFO - Using connection ID 'postgres_localhost' for task execution.
[2024-08-07T15:30:56.783+0000] {taskinstance.py:441} INFO - ::group::Post task execution logs
[2024-08-07T15:30:56.784+0000] {taskinstance.py:2905} ERROR - Task failed with exception
Traceback (most recent call last):
  File "/home/airflow/.local/lib/python3.12/site-packages/airflow/models/taskinstance.py", line 465, in _execute_task
    result = _execute_callable(context=context, **execute_callable_kwargs)
             ^^^^^^^^^^^^^^^^^^^^^^^^^^^^^^^^^^^^^^^^^^^^^^^^^^^^^^^^^^^^^
  File "/home/airflow/.local/lib/python3.12/site-packages/airflow/models/taskinstance.py", line 432, in _execute_callable
    return execute_callable(context=context, **execute_callable_kwargs)
           ^^^^^^^^^^^^^^^^^^^^^^^^^^^^^^^^^^^^^^^^^^^^^^^^^^^^^^^^^^^^
  File "/home/airflow/.local/lib/python3.12/site-packages/airflow/models/baseoperator.py", line 401, in wrapper
    return func(self, *args, **kwargs)
           ^^^^^^^^^^^^^^^^^^^^^^^^^^^
  File "/home/airflow/.local/lib/python3.12/site-packages/airflow/operators/python.py", line 235, in execute
    return_value = self.execute_callable()
                   ^^^^^^^^^^^^^^^^^^^^^^^
  File "/home/airflow/.local/lib/python3.12/site-packages/airflow/operators/python.py", line 252, in execute_callable
    return self.python_callable(*self.op_args, **self.op_kwargs)
           ^^^^^^^^^^^^^^^^^^^^^^^^^^^^^^^^^^^^^^^^^^^^^^^^^^^^^
  File "/opt/airflow/dags/dag_prueba_tecnica.py", line 65, in limpiezaDatos
    pg_hook.insert_rows('table_name2', df_normado)
  File "/home/airflow/.local/lib/python3.12/site-packages/airflow/providers/common/sql/hooks/sql.py", line 606, in insert_rows
    cur.executemany(sql, values)
psycopg2.errors.UndefinedTable: relation "table_name2" does not exist
LINE 1: INSERT INTO table_name2  VALUES ('r','e','v','_','M','e','a'...
                    ^

[2024-08-07T15:30:56.790+0000] {taskinstance.py:1206} INFO - Marking task as UP_FOR_RETRY. dag_id=dag_prueba_tecnica, task_id=limpieza, run_id=scheduled__2024-07-28T00:00:00+00:00, execution_date=20240728T000000, start_date=20240807T153042, end_date=20240807T153056
[2024-08-07T15:30:56.802+0000] {standard_task_runner.py:110} ERROR - Failed to execute job 98 for task limpieza (relation "table_name2" does not exist
LINE 1: INSERT INTO table_name2  VALUES ('r','e','v','_','M','e','a'...
                    ^
; 255)
[2024-08-07T15:30:56.932+0000] {local_task_job_runner.py:243} INFO - Task exited with return code 1
[2024-08-07T15:30:56.947+0000] {taskinstance.py:3503} INFO - 0 downstream tasks scheduled from follow-on schedule check
[2024-08-07T15:30:56.950+0000] {local_task_job_runner.py:222} INFO - ::endgroup::
