[2024-08-07T16:09:41.931+0000] {local_task_job_runner.py:120} INFO - ::group::Pre task execution logs
[2024-08-07T16:09:41.948+0000] {taskinstance.py:2076} INFO - Dependencies all met for dep_context=non-requeueable deps ti=<TaskInstance: dag_prueba_tecnica.entrenamiento scheduled__2024-08-05T00:00:00+00:00 [queued]>
[2024-08-07T16:09:41.953+0000] {taskinstance.py:2076} INFO - Dependencies all met for dep_context=requeueable deps ti=<TaskInstance: dag_prueba_tecnica.entrenamiento scheduled__2024-08-05T00:00:00+00:00 [queued]>
[2024-08-07T16:09:41.954+0000] {taskinstance.py:2306} INFO - Starting attempt 4 of 6
[2024-08-07T16:09:41.964+0000] {taskinstance.py:2330} INFO - Executing <Task(PythonOperator): entrenamiento> on 2024-08-05 00:00:00+00:00
[2024-08-07T16:09:41.971+0000] {warnings.py:112} WARNING - /home/***/.local/lib/python3.12/site-packages/***/task/task_runner/standard_task_runner.py:62: DeprecationWarning: This process (pid=558) is multi-threaded, use of fork() may lead to deadlocks in the child.
  pid = os.fork()

[2024-08-07T16:09:41.972+0000] {standard_task_runner.py:64} INFO - Started process 571 to run task
[2024-08-07T16:09:41.972+0000] {standard_task_runner.py:90} INFO - Running: ['***', 'tasks', 'run', 'dag_prueba_tecnica', 'entrenamiento', 'scheduled__2024-08-05T00:00:00+00:00', '--job-id', '172', '--raw', '--subdir', 'DAGS_FOLDER/dag_prueba_tecnica.py', '--cfg-path', '/tmp/tmph5k__jdi']
[2024-08-07T16:09:41.972+0000] {standard_task_runner.py:91} INFO - Job 172: Subtask entrenamiento
[2024-08-07T16:09:42.011+0000] {task_command.py:426} INFO - Running <TaskInstance: dag_prueba_tecnica.entrenamiento scheduled__2024-08-05T00:00:00+00:00 [running]> on host 278ba5711b2c
[2024-08-07T16:09:42.073+0000] {taskinstance.py:2648} INFO - Exporting env vars: AIRFLOW_CTX_DAG_OWNER='miguel_guimarey' AIRFLOW_CTX_DAG_ID='dag_prueba_tecnica' AIRFLOW_CTX_TASK_ID='entrenamiento' AIRFLOW_CTX_EXECUTION_DATE='2024-08-05T00:00:00+00:00' AIRFLOW_CTX_TRY_NUMBER='4' AIRFLOW_CTX_DAG_RUN_ID='scheduled__2024-08-05T00:00:00+00:00'
[2024-08-07T16:09:42.074+0000] {taskinstance.py:430} INFO - ::endgroup::
[2024-08-07T16:09:42.081+0000] {taskinstance.py:441} INFO - ::group::Post task execution logs
[2024-08-07T16:09:42.082+0000] {taskinstance.py:2905} ERROR - Task failed with exception
Traceback (most recent call last):
  File "/home/airflow/.local/lib/python3.12/site-packages/airflow/models/taskinstance.py", line 465, in _execute_task
    result = _execute_callable(context=context, **execute_callable_kwargs)
             ^^^^^^^^^^^^^^^^^^^^^^^^^^^^^^^^^^^^^^^^^^^^^^^^^^^^^^^^^^^^^
  File "/home/airflow/.local/lib/python3.12/site-packages/airflow/models/taskinstance.py", line 432, in _execute_callable
    return execute_callable(context=context, **execute_callable_kwargs)
           ^^^^^^^^^^^^^^^^^^^^^^^^^^^^^^^^^^^^^^^^^^^^^^^^^^^^^^^^^^^^
  File "/home/airflow/.local/lib/python3.12/site-packages/airflow/models/baseoperator.py", line 401, in wrapper
    return func(self, *args, **kwargs)
           ^^^^^^^^^^^^^^^^^^^^^^^^^^^
  File "/home/airflow/.local/lib/python3.12/site-packages/airflow/operators/python.py", line 235, in execute
    return_value = self.execute_callable()
                   ^^^^^^^^^^^^^^^^^^^^^^^
  File "/home/airflow/.local/lib/python3.12/site-packages/airflow/operators/python.py", line 252, in execute_callable
    return self.python_callable(*self.op_args, **self.op_kwargs)
           ^^^^^^^^^^^^^^^^^^^^^^^^^^^^^^^^^^^^^^^^^^^^^^^^^^^^^
  File "/opt/airflow/dags/dag_prueba_tecnica.py", line 70, in entrenamientoDatos
    df_normado =  pd.read_json(data)
                  ^^^^^^^^^^^^^^^^^^
  File "/home/airflow/.local/lib/python3.12/site-packages/pandas/io/json/_json.py", line 780, in read_json
    json_reader = JsonReader(
                  ^^^^^^^^^^^
  File "/home/airflow/.local/lib/python3.12/site-packages/pandas/io/json/_json.py", line 893, in __init__
    data = self._get_data_from_filepath(filepath_or_buffer)
           ^^^^^^^^^^^^^^^^^^^^^^^^^^^^^^^^^^^^^^^^^^^^^^^^
  File "/home/airflow/.local/lib/python3.12/site-packages/pandas/io/json/_json.py", line 933, in _get_data_from_filepath
    self.handles = get_handle(
                   ^^^^^^^^^^^
  File "/home/airflow/.local/lib/python3.12/site-packages/pandas/io/common.py", line 718, in get_handle
    ioargs = _get_filepath_or_buffer(
             ^^^^^^^^^^^^^^^^^^^^^^^^
  File "/home/airflow/.local/lib/python3.12/site-packages/pandas/io/common.py", line 460, in _get_filepath_or_buffer
    raise ValueError(msg)
ValueError: Invalid file path or buffer object type: <class 'NoneType'>
[2024-08-07T16:09:42.090+0000] {taskinstance.py:1206} INFO - Marking task as UP_FOR_RETRY. dag_id=dag_prueba_tecnica, task_id=entrenamiento, run_id=scheduled__2024-08-05T00:00:00+00:00, execution_date=20240805T000000, start_date=20240807T160941, end_date=20240807T160942
[2024-08-07T16:09:42.099+0000] {standard_task_runner.py:110} ERROR - Failed to execute job 172 for task entrenamiento (Invalid file path or buffer object type: <class 'NoneType'>; 571)
[2024-08-07T16:09:42.146+0000] {local_task_job_runner.py:243} INFO - Task exited with return code 1
[2024-08-07T16:09:42.160+0000] {taskinstance.py:3503} INFO - 0 downstream tasks scheduled from follow-on schedule check
[2024-08-07T16:09:42.163+0000] {local_task_job_runner.py:222} INFO - ::endgroup::
